Workbook

Sheet Executive Dashboard
B2: SME FINANCE READINESS — EXECUTIVE DASHBOARD
B3: Evidence-informed prototype | Decision-support tool | Not a credit approval or lender score
B5: OVERALL READINESS | D5: CLASSIFICATION | F5: TOP PRIORITY
B7: =Scoring!E15 -> 86.240079 | D7: =Scoring!E16 -> Ready | F7: =IFERROR(INDEX(Recommendations!$B$7:$B$22,MATCH("High",Recommendations!$A$7:$A$22,0)),"No High Priority") -> Liquidity
B10: READINESS DIMENSIONS
B11: Dimension | C11: Score | D11: Maximum | E11: % of Maximum
B12: Financial Health | C12: =SUM(Scoring!E4:E6) -> 21.875 | D12: 25 | E12: =C12/D12 -> 0.875
B13: Cash-Flow Management | C13: =SUM(Scoring!E7:E9) -> 17.222222 | D13: 20 | E13: =C13/D13 -> 0.86111111
B14: Financial Records & Transparency | C14: =Scoring!E10 -> 17.142857 | D14: 20 | E14: =C14/D14 -> 0.85714286
B15: Debt & Repayment Capacity | C15: =Scoring!E11 -> 20 | D15: 20 | E15: =C15/D15 -> 1
B16: Financial Planning | C16: =Scoring!E12 -> 10 | D16: 15 | E16: =C16/D16 -> 0.66666667
B19: KEY FINANCIAL INDICATORS
B20: Indicator | C20: Value | D20: Interpretation | E20: Indicator | F20: Value | G20: Interpretation
B21: Current Ratio | C21: =Calculations!C5 -> 1.5 | D21: Liquidity | E21: Operating Profit Margin | F21: =Calculations!C6 -> 0.25 | G21: Profitability
B22: Debt / Assets | C22: =Calculations!C7 -> 0.3125 | D22: Leverage | E22: Cash-Flow Coverage | F22: =Calculations!C9 -> 1.3333333 | G22: Inflow / outflow
B23: Cash Reserve | C23: =Calculations!C10 -> 2 | D23: Months | E23: Debt-Service Coverage Proxy | F23: =Calculations!C11 -> 3.7313433 | G23: Cash available / debt payment
B24: Recordkeeping Practices | C24: =Calculations!C12 -> 0.85714286 | D24: Share completed | E24: Financial Planning Practices | F24: =Calculations!C13 -> 0.66666667 | G24: Share completed
B26: WHAT-IF IMPROVEMENT
B27: Current Score | C27: =Scoring!E15 -> 86.240079
B28: Scenario Score | C28: ='What-If V2'!C34 -> 0
B29: Score Change | C29: ='What-If V2'!D34 -> 0
B30: Scenario Classification | C30: ='What-If V2'!C35 -> 0
B32: IMPROVEMENT PRIORITIES
B33: Area | C33: Status | D33: Priority | E33: Recommended Action
B34: =Recommendations!A35 -> Liquidity | C34: =Recommendations!C35 -> Strong | D34: =Recommendations!E35 -> Low | E34: =Recommendations!D35 -> Maintain liquidity discipline.
B35: =Recommendations!A36 -> Profitability | C35: =Recommendations!C36 -> Strong | D35: =Recommendations!E36 -> Low | E35: =Recommendations!D36 -> Protect operating margins while scaling.
B36: =Recommendations!A37 -> Leverage | C36: =Recommendations!C37 -> Moderate | D36: =Recommendations!E37 -> Medium | E36: =Recommendations!D37 -> Monitor leverage before additional debt.
B37: =Recommendations!A38 -> Cash Flow | C37: =Recommendations!C38 -> Strong | D37: =Recommendations!E38 -> Low | E37: =Recommendations!D38 -> Maintain regular cash-flow monitoring.
B38: =Recommendations!A39 -> Cash Reserve | C38: =Recommendations!C39 -> Moderate | D38: =Recommendations!E39 -> Medium | E38: =Recommendations!D39 -> Work toward a stronger reserve.
B41: Interpretation note: the readiness score is an internal prototype. Thresholds and weights are normalization choices informed by literature and should be empirically validated before use for real lending, investment, or regulatory decisions.
B44: Demo note: | C44: Inputs are illustrative and can be replaced with actual SME data.
B45: Workbook navigation: | C45: Inputs → Calculations → Scoring → Diagnostics → Recommendations → What-If V2 → Methodology → QC & Validation

Sheet Inputs
A1: SME Finance Readiness & Improvement Simulator
A2: Illustrative demo values are preloaded for portfolio demonstration. Replace the yellow cells with real SME information.
A4: Category | B4: Input | C4: Value | D4: Unit / Response Type
A5: Business Information | B5: Business age | C5: 5 | D5: Years
A6: Business Information | B6: Number of employees | C6: 12 | D6: Number
A7: Business Information | B7: Annual revenue | C7: 12000000 | D7: PKR
A8: Business Information | B8: Annual operating expenses | C8: 9000000 | D8: PKR
A9: Business Information | B9: Total assets | C9: 8000000 | D9: PKR
A10: Business Information | B10: Current assets | C10: 3000000 | D10: PKR
A11: Business Information | B11: Current liabilities | C11: 2000000 | D11: PKR
A12: Business Information | B12: Total debt | C12: 2500000 | D12: PKR
A13: Business Information | B13: Annual interest expense | C13: 300000 | D13: PKR
A14: Business Information | B14: Annual principal repayment | C14: 500000 | D14: PKR
A15: Business Information | B15: Cash & cash equivalents | C15: 1200000 | D15: PKR
A16: Cash-Flow Management | B16: Average monthly cash inflow | C16: 1000000 | D16: PKR
... A19: Cash-Flow Management | B19: Cash reserve | C19: 2 | D19: Months
A20: Cash-Flow Management | B20: Cash-flow monitoring frequency | C20: Monthly | D20: Monthly / Quarterly / Less often
A21: Financial Records | B21: Formal accounting records maintained | C21: Yes | D21: Yes / No
A22: Financial Records | B22: Financial statements prepared | C22: Yes | D22: Yes / No
A23: Financial Records | B23: Business bank account used | C23: Yes | D23: Yes / No
A24: Financial Records | B24: Business and personal finances separated | C24: Yes | D24: Yes / No
A25: Financial Records | B25: Records updated regularly | C25: Yes | D25: Yes / No
A26: Financial Records | B26: Accounting software used | C26: No | D26: Yes / No
A27: Financial Records | B27: At least 2 years of financial records available | C27: Yes | D27: Yes / No
A28: Financial Planning | B28: Annual budget prepared | C28: Yes | D28: Yes / No
A29: Financial Planning | B29: Revenue forecast prepared | C29: Yes | D29: Yes / No
A30: Financial Planning | B30: Expense forecast prepared | C30: Yes | D30: Yes / No
A31: Financial Planning | B31: Actual vs. budget reviewed | C31: No | D31: Yes / No
... A33: Financial Planning | B33: Emergency financial plan exists | C33: No | D33: Yes / No

Sheet Calculations
A1: Financial Calculations
A3: Indicator | B3: Formula | C3: Result | D3: Interpretation
A4: Operating profit | B4: Revenue − operating expenses | C4: =Inputs!C7-Inputs!C8 -> 3000000 | D4: Positive is generally stronger
A5: Current ratio | B5: Current assets ÷ current liabilities | C5: =IFERROR(Inputs!C10/Inputs!C11,"") -> 1.5 | D5: Higher generally indicates stronger short-term liquidity
A6: Operating profit margin | B6: Operating profit ÷ revenue | C6: =IFERROR(C4/Inputs!C7,"") -> 0.25 | D6: Higher generally indicates stronger operating profitability
A7: Debt-to-asset ratio | B7: Total debt ÷ total assets | C7: =IFERROR(Inputs!C12/Inputs!C9,"") -> 0.3125 | D7: Lower generally indicates lower leverage
A8: Monthly net cash flow | B8: Monthly inflow − monthly outflow | C8: =Inputs!C16-Inputs!C17 -> 250000 | D8: Positive means inflow exceeds outflow
A9: Cash-flow coverage | B9: Monthly inflow ÷ monthly outflow | C9: =IFERROR(Inputs!C16/Inputs!C17,"") -> 1.3333333 | D9: Higher indicates greater operating cash coverage
A10: Cash reserve | B10: Direct input | C10: =Inputs!C19 -> 2 | D10: Months of cash reserve
A11: Cash-flow debt-service coverage (proxy) | B11: (Monthly inflow − monthly outflow) ÷ monthly debt payment | C11: =IFERROR((Inputs!C16-Inputs!C17)/Inputs!C18,"") -> 3.7313433 | D11: Cash generated before debt service relative to recurring debt payment; proxy, not formal lender DSCR.
A12: Recordkeeping practices | B12: Yes responses ÷ 7 | C12: =COUNTIF(Inputs!C21:C27,"Yes")/7 -> 0.85714286 | D12: Share of recommended practices present
A13: Planning practices | B13: Yes responses ÷ 6 | C13: =COUNTIF(Inputs!C28:C33,"Yes")/6 -> 0.66666667 | D13: Share of recommended practices present

Sheet Scoring
A1: Finance Readiness Scoring Engine
A3: Dimension | B3: Weight | C3: Component | D3: Max Points | E3: Current Points | F3: Scoring Logic
A4: Financial Health | B4: 25 | C4: Liquidity | D4: 8 | E4: =IF(Calculations!C5="","",MIN(8,MAX(0,Calculations!C5/2*8))) -> 6 | F4: Current ratio 0–2 → 0–8; capped.
A5: Financial Health | B5: 25 | C5: Profitability | D5: 9 | E5: =IF(Calculations!C6="","",MIN(9,MAX(0,Calculations!C6/0.2*9))) -> 9 | F5: Operating margin 0–20% → 0–9; capped.
A6: Financial Health | B6: 25 | C6: Leverage | D6: 8 | E6: =IF(Calculations!C7="","",MIN(8,MAX(0,(1-Calculations!C7)/0.8*8))) -> 6.875 | F6: Debt/assets 0–80% → 8–0.
A7: Cash-Flow Management | B7: 20 | C7: Cash-flow coverage | D7: 10 | E7: =IF(Calculations!C9="","",MIN(10,MAX(0,Calculations!C9/1.5*10))) -> 8.8888889 | F7: Inflow/outflow 0–1.5 → 0–10; capped.
A8: Cash-Flow Management | B8: 20 | C8: Cash reserve | D8: 5 | E8: =IF(Inputs!C19="","",MIN(5,MAX(0,Inputs!C19/3*5))) -> 3.3333333 | F8: 0–3 months → 0–5; capped.
A9: Cash-Flow Management | B9: 20 | C9: Monitoring frequency | D9: 5 | E9: =IF(Inputs!C20="","",IF(Inputs!C20="Monthly",5,IF(Inputs!C20="Quarterly",3,1))) -> 5 | F9: Monthly 5; quarterly 3; less often 1.
A10: Financial Records & Transparency | B10: 20 | C10: Recordkeeping | D10: 20 | E10: =IF(COUNTA(Inputs!C21:C27)=0,"",COUNTIF(Inputs!C21:C27,"Yes")/7*20) -> 17.142857 | F10: Seven practices weighted equally.
A11: Debt & Repayment Capacity | B11: 20 | C11: Debt-service capacity | D11: 20 | E11: =IF(Calculations!C11="","",MIN(20,MAX(0,Calculations!C11/2*20))) -> 20 | F11: Cash-flow DSCR proxy 0–2 → 0–20; capped. Proxy is not a lender underwriting DSCR.
A12: Financial Planning | B12: 15 | C12: Planning practices | D12: 15 | E12: =IF(COUNTA(Inputs!C28:C33)=0,"",COUNTIF(Inputs!C28:C33,"Yes")/6*15) -> 10 | F12: Six practices weighted equally.
A15: TOTAL FINANCE READINESS SCORE | E15: =SUM(E4:E12) -> 86.240079
A16: Classification | E16: =IF(E15="","",IF(E15>=75,"Ready",IF(E15>=50,"Developing","Needs Improvement"))) -> Ready
A18: Methodology note
A19: This is an internally designed prototype readiness index, not a bank credit score or externally validated certification. The weighting and normalization ranges will be documented and reviewed against relevant SME finance literature in the final project.

Sheet Dashboard
A1: Detailed Dashboard (Legacy)
A3: Overall Readiness Score | B3: =Scoring!E15 -> 86.240079 | C3: / 100
A4: Classification | B4: =Scoring!E16 -> Ready
A6: Dimension | B6: Max | C6: Score | D6: Status
A7: Financial Health | B7: 25 | C7: =SUM(Scoring!E4:E6) -> 21.875 | D7: =IF(C7="","",IF(C7/B7>=0.75,"Strong",IF(C7/B7>=0.5,"Developing","Priority"))) -> Strong
A8: Cash-Flow Management | B8: 20 | C8: =SUM(Scoring!E7:E9) -> 17.222222 | D8: =IF(C8="","",IF(C8/B8>=0.75,"Strong",IF(C8/B8>=0.5,"Developing","Priority"))) -> Strong
A9: Financial Records & Transparency | B9: 20 | C9: =Scoring!E10 -> 17.142857 | D9: =IF(C9="","",IF(C9/B9>=0.75,"Strong",IF(C9/B9>=0.5,"Developing","Priority"))) -> Strong
A10: Debt & Repayment Capacity | B10: 20 | C10: =Scoring!E11 -> 20 | D10: =IF(C10="","",IF(C10/B10>=0.75,"Strong",IF(C10/B10>=0.5,"Developing","Priority"))) -> Strong
A11: Financial Planning | B11: 15 | C11: =Scoring!E12 -> 10 | D11: =IF(C11="","",IF(C11/B11>=0.75,"Strong",IF(C11/B11>=0.5,"Developing","Priority"))) -> Developing
A14: Priority diagnostic | D14: Recommended actions
A15: Financial Health | B15: =IF(C7/B7<0.5,"Priority weakness","Adequate") -> Adequate | D15: =IF(B15="Priority weakness","Review liquidity, profitability and leverage; improve the weakest underlying ratio.","Maintain current financial-health practices.") -> Maintain current financial-health practices.
A16: Cash-Flow Management | B16: =IF(C8/B8<0.5,"Priority weakness","Adequate") -> Adequate | D16: =IF(B16="Priority weakness","Monitor cash flow monthly and build a cash reserve; review recurring cash outflows.","Maintain regular cash-flow monitoring.") -> Maintain regular cash-flow monitoring.
A17: Financial Records | B17: =IF(C9/B9<0.5,"Priority weakness","Adequate") -> Adequate | D17: =IF(B17="Priority weakness","Strengthen formal records, financial statements, account separation and record updating.","Maintain consistent financial documentation.") -> Maintain consistent financial documentation.
A18: Debt Capacity | B18: =IF(C10/B10<0.5,"Priority weakness","Adequate") -> Adequate | D18: =IF(B18="Priority weakness","Review debt obligations and repayment capacity before taking on additional debt.","Continue monitoring debt-service capacity.") -> Continue monitoring debt-service capacity.
A19: Financial Planning | B19: =IF(C11/B11<0.5,"Priority weakness","Adequate") -> Adequate | D19: =IF(B19="Priority weakness","Introduce budgeting, revenue/expense forecasting and actual-vs-budget review.","Maintain and periodically update financial plans.") -> Maintain and periodically update financial plans.

Sheet What-If
A1: What-If Improvement Simulator
A2: Change hypothetical improvement assumptions below to see an indicative score.
A4: Variable | B4: Current | C4: Scenario | D4: Unit | E4: Change | F4: Purpose
A5: Annual revenue | B5: =Inputs!C7 -> 12000000 | C5: =B5 -> 12000000 | D5: PKR | E5: Scenario value | F5: Test profitability improvement
A6: Annual operating expenses | B6: =Inputs!C8 -> 9000000 | C6: =B6 -> 9000000 | D6: PKR | E6: Scenario value | F6: Test cost management
A7: Current assets | B7: =Inputs!C10 -> 3000000 | C7: =B7 -> 3000000 | D7: PKR | E7: Scenario value | F7: Test liquidity improvement
A8: Current liabilities | B8: =Inputs!C11 -> 2000000 | C8: =B8 -> 2000000 | D8: PKR | E8: Scenario value | F8: Test short-term obligation reduction
A9: Total debt | B9: =Inputs!C12 -> 2500000 | C9: =B9 -> 2500000 | D9: PKR | E9: Scenario value | F9: Test deleveraging
A10: Monthly cash inflow | B10: =Inputs!C16 -> 1000000 | C10: =B10 -> 1000000 | D10: PKR | E10: Scenario value | F10: Test stronger cash generation
A11: Monthly cash outflow | B11: =Inputs!C17 -> 750000 | C11: =B11 -> 750000 | D11: PKR | E11: Scenario value | F11: Test lower cash outflow
A12: Cash reserve | B12: =Inputs!C19 -> 2 | C12: =B12 -> 2 | D12: Months | E12: Scenario value | F12: Test liquidity buffer
A15: Baseline score | B15: =Scoring!E15 -> 86.240079
A16: Scenario score (indicative) | B16: =IF(COUNTA(C5:C12)=0,"",MIN(100,MAX(0,(MIN(8,MAX(0,(C7/C8)/2*8))+MIN(9,MAX(0,((C5-C6)/C5)/0.2*9))+MIN(8,MAX(0,(1-C9/Inputs!C9)/0.8*8))+MIN(10,MAX(0,(C10/C11)/1.5*10))+MIN(5,MAX(0,C12/3*5))+Scoring!E9+Scoring!E10+Scoring!E11+Scoring!E12)))) -> 86.240079
A17: Indicative change | B17: =IF(B16="","",B16-B15) -> 0
A19: Important
A20: The What-If score is an exploratory scenario, not a forecast of financing approval or business performance. It holds several current practices constant and changes selected financial inputs.

Sheet Diagnostics
A1: SME Finance Readiness — Detailed Diagnostics
A3: Overall Score | B3: =Scoring!E15 -> 86.240079
A4: Classification | B4: =Scoring!E16 -> Ready
A5: Purpose | B5: Explains the underlying indicators behind the readiness score and provides targeted management actions.
A7: Metric | B7: Current Value | C7: Status | D7: Why It Matters | E7: Recommended Action | F7: Source
A8: Current Ratio | B8: =Calculations!C5 -> 1.5 | C8: =IF(B8>=1.5,"Strong",IF(B8>=1,"Moderate","Needs attention")) -> Strong | D8: Measures short-term liquidity relative to current liabilities. | E8: =IF(C8="Needs attention","Increase liquid current assets and/or reduce short-term liabilities.",IF(C8="Moderate","Build a stronger working-capital buffer.","Maintain current liquidity discipline.")) -> Maintain current liquidity discipline. | F8: Calculations
A9: Operating Profit Margin | B9: =Calculations!C6 -> 0.25 | C9: =IF(B9>=0.15,"Strong",IF(B9>=0.08,"Moderate","Needs attention")) -> Strong | D9: Shows the operating profit retained from revenue. | E9: =IF(C9="Needs attention","Review major operating costs and pricing; target sustainable margin improvement.",IF(C9="Moderate","Monitor cost efficiency and pricing regularly.","Protect margins while scaling revenue.")) -> Protect margins while scaling revenue. | F9: Calculations
A10: Debt / Assets | B10: =Calculations!C7 -> 0.3125 | C10: =IF(B10<=0.3,"Strong",IF(B10<=0.5,"Moderate","Needs attention")) -> Moderate | D10: Indicates how much of the asset base is financed by debt. | E10: =IF(C10="Needs attention","Prioritize debt reduction and avoid unnecessary new borrowing.",IF(C10="Moderate","Monitor leverage before taking additional debt.","Maintain prudent leverage.")) -> Monitor leverage before taking additional debt. | F10: Calculations
A11: Cash-Flow Coverage | B11: =Calculations!C9 -> 1.3333333 | C11: =IF(B11>=1.25,"Strong",IF(B11>=1,"Moderate","Needs attention")) -> Strong | D11: Compares monthly cash inflows with monthly cash outflows. | E11: =IF(C11="Needs attention","Improve collections, reduce avoidable outflows, and monitor cash more frequently.",IF(C11="Moderate","Strengthen cash buffers and collection discipline.","Maintain regular cash-flow monitoring.")) -> Maintain regular cash-flow monitoring. | F11: Calculations
A12: Cash Reserve | B12: =Inputs!C19 -> 2 | C12: =IF(B12>=3,"Strong",IF(B12>=1.5,"Moderate","Needs attention")) -> Moderate | D12: Shows the number of months of cash reserve available. | E12: =IF(C12="Needs attention","Build an emergency cash reserve gradually.",IF(C12="Moderate","Work toward at least three months of core cash needs.","Maintain the reserve.")) -> Work toward at least three months of core cash needs. | F12: Inputs
A13: Cash-flow Debt-Service Coverage (Proxy) | B13: =Calculations!C11 -> 3.7313433 | C13: =IF(B13>=1.5,"Strong",IF(B13>=1,"Moderate","Needs attention")) -> Strong | D13: Compares cash generated before debt service with recurring debt payment. | E13: =IF(C13="Needs attention","Reduce debt-service pressure and/or strengthen operating cash generation.",IF(C13="Moderate","Improve recurring cash generation before adding significant debt.","Maintain debt-service discipline.")) -> Maintain debt-service discipline. | F13: Calculations!C11
A14: Recordkeeping Practices | B14: =Calculations!C12 -> 0.85714286 | C14: =IF(B14>=0.85,"Strong",IF(B14>=0.6,"Moderate","Needs attention")) -> Strong | D14: Formal records improve transparency and support financing decisions. | E14: =IF(C14="Needs attention","Formalize accounting records, statements, banking separation, and regular updates.",IF(C14="Moderate","Close gaps in documentation and reporting.","Keep records current and organized.")) -> Keep records current and organized. | F14: Calculations
A15: Financial Planning Practices | B15: =Calculations!C13 -> 0.66666667 | C15: =IF(B15>=0.85,"Strong",IF(B15>=0.6,"Moderate","Needs attention")) -> Moderate | D15: Planning indicates whether management actively anticipates financial needs. | E15: =IF(C15="Needs attention","Introduce budgeting, forecasts, targets, and contingency planning.",IF(C15="Moderate","Make planning and variance review more consistent.","Maintain formal planning routines.")) -> Make planning and variance review more consistent. | F15: Calculations
A18: Dimension Summary
A19: Dimension | B19: Maximum | C19: Score | D19: Share of Dimension | E19: Status | F19: V1 Source
A20: Financial Health | B20: 25 | C20: =SUM(Scoring!E4:E6) -> 21.875 | D20: =C20/B20 -> 0.875 | E20: =IF(D20>=0.75,"Strong",IF(D20>=0.5,"Developing","Needs attention")) -> Strong | F20: Original V1 scoring engine
A21: Cash-Flow Management | B21: 20 | C21: =SUM(Scoring!E7:E9) -> 17.222222 | D21: =C21/B21 -> 0.86111111 | E21: =IF(D21>=0.75,"Strong",IF(D21>=0.5,"Developing","Needs attention")) -> Strong | F21: Original V1 scoring engine
A22: Financial Records & Transparency | B22: 20 | C22: =Scoring!E10 -> 17.142857 | D22: =C22/B22 -> 0.85714286 | E22: =IF(D22>=0.75,"Strong",IF(D22>=0.5,"Developing","Needs attention")) -> Strong | F22: Original V1 scoring engine
A23: Debt & Repayment Capacity | B23: 20 | C23: =Scoring!E11 -> 20 | D23: =C23/B23 -> 1 | E23: =IF(D23>=0.75,"Strong",IF(D23>=0.5,"Developing","Needs attention")) -> Strong | F23: Original V1 scoring engine
A24: Financial Planning | B24: 15 | C24: =Scoring!E12 -> 10 | D24: =C24/B24 -> 0.66666667 | E24: =IF(D24>=0.75,"Strong",IF(D24>=0.5,"Developing","Needs attention")) -> Developing | F24: Original V1 scoring engine
A27: Methodology status
A28: V3 evidence layer added; V2 scoring engine remains unchanged. See 'V3 Methodology' and 'Literature & Evidence'.

Sheet Methodology
A1: SME Finance Readiness Simulator — Methodology
A3: Purpose | B3: Internal decision-support prototype combining financial indicators with management practices to assess SME finance readiness.
A4: Core framework | B4: Financial Health 25; Cash-Flow Management 20; Financial Records & Transparency 20; Debt & Repayment Capacity 20; Financial Planning 15.
A5: Classification | B5: 75–100 Ready; 50–74.99 Developing; below 50 Needs Improvement. These are internal prototype categories, not official lending standards.
A6: Financial condition vs readiness | B6: Financial condition describes the numbers; readiness also considers records, transparency, planning, cash management and debt capacity.
A7: Debt-service metric | B7: The debt-service measure is an indicative prototype proxy, not a formal lender DSCR.
A8: What-If limitation | B8: Scenario results are exploratory and should not be presented as predictions of financing approval or future business performance.
A9: Future validation | B9: Weights, thresholds and practice measures should be reviewed against SME-finance literature and, ideally, tested with real SME observations before external validation claims.

Sheet Literature & Evidence
A1: Evidence source | B1: What it supports | C1: How used in simulator | D1: Caveat
A2: OECD (2026) Financing SMEs and Entrepreneurs 2026 | B2: SME finance monitoring should use useful, feasible and timely indicators; framework covers financing structure, credit conditions, financial health and payment delays. | C2: Supports the overall multi-dimensional architecture rather than a single profitability score. | D2: OECD is a framework for monitoring SME finance, not a validated firm-level readiness score.
A3: OECD (2024) Financing SMEs and Entrepreneurs 2024 | B3: Financial health and payment delays are relevant to SME financing conditions; access to finance involves debt, equity and financing conditions. | C3: Supports Financial Health and Cash-Flow Management dimensions. | D3: Country-level indicators do not establish firm-level thresholds.
A4: Brijlal, Enow & Isaacs (2014), International Review of Economics Education | B4: SMMEs often rely on external accounting support and may have difficulty interpreting financial-statement information; financial-management education is relevant to cash-flow risk. | C4: Supports Records & Transparency and the need for actionable recommendations. | D4: Evidence is South Africa-specific and observational.
A5: Kolawole & Oladejo (2026), Bayero Business Review | B5: Record-keeping was significantly associated with SME performance and partially moderated the access-to-finance/performance relationship in a Kano SME sample. | C5: Supports treating record-keeping as a distinct readiness capability. | D5: Single regional sample; does not validate our 20-point weight.
A6: Okello (2022), Makerere University | B6: Cash-flow budget, monitoring and cash-flow-cycle control were positively correlated with SME financial performance in a Ugandan sample. | C6: Supports Cash-Flow Management indicators such as monitoring and reserve/cash coverage. | D6: Correlation does not prove causation; context differs from Pakistan.
A7: Elom & Atah (2025), Journal of International Cooperation and Development | B7: Budgeting strategy and cash-flow management were examined as financial-management strategies affecting MSE performance. | C7: Supports Financial Planning and Cash-Flow Management as practical management capabilities. | D7: MSE evidence from Calabar; not a financing-approval model.
A8: Agri-SME managers study (2024), Scientific African | B8: Financial-management practices and perceived usefulness/ease of use were positively associated with organizational performance; technology adoption remained limited. | C8: Supports including accounting-software use and practical financial-management practices as diagnostic items. | D8: Agri-SME context; not directly a financing-readiness validation study.

Sheet V3 Methodology
A1: SME Finance Readiness & Improvement Simulator — V3 Methodology
A2: Purpose | B2: An internal decision-support prototype that diagnoses finance-related strengths and weaknesses in an SME and simulates improvement scenarios. It is not a credit score, loan-approval model, or prediction of financing approval.
A3: Conceptual distinction | B3: Financial health describes the firm's current financial condition. Finance readiness additionally considers whether the firm has the records, cash-flow discipline, repayment capacity and planning practices needed to present and manage a financing case.
A4: Dimension 1 — Financial Health | B4: 25 points: liquidity (8), profitability (9), leverage (8). Indicators: current ratio, operating profit margin, debt/assets.
A5: Dimension 2 — Cash-Flow Management | B5: 20 points: cash-flow coverage (10), cash reserve (5), monitoring frequency (5). These capture near-term liquidity discipline and monitoring behavior.
A6: Dimension 3 — Financial Records & Transparency | B6: 20 points: seven binary practices, equally weighted in V2: formal accounting records; financial statements; business bank account; separation of personal/business finances; regular updates; accounting software; ≥2 years of records.
A7: Dimension 4 — Debt & Repayment Capacity | B7: 20 points: prototype debt-service capacity indicator. V2 uses an internal proxy; this should be replaced/reconciled with a formally defined debt-service metric in a later validation version rather than presenting it as standard DSCR.
A8: Dimension 5 — Financial Planning | B8: 15 points: six binary practices, equally weighted in V2: annual budget; revenue forecast; expense forecast; actual-vs-budget review; financial targets; emergency financial plan.
A9: Why multiple dimensions | B9: OECD's SME finance framework uses multiple indicator families covering financing structure, credit conditions and financial health rather than one measure. Research also links record-keeping, cash-flow management and budgeting practices with SME management/performance outcomes. This supports a multidimensional diagnostic design.
A10: Weights | B10: The 25/20/20/20/15 weights are prototype design choices, not empirically estimated weights. They should be treated as transparent expert-design weights pending validation with SME/bank data.
A11: Thresholds | B11: V2 thresholds are normalization rules chosen for the prototype (e.g., current ratio 0–2; operating margin 0–20%; debt/assets 0–80%). They are not presented as universal SME standards and should be calibrated using sector/country evidence in future versions.
A12: Classification | B12: 75–100 = Ready; 50–74.99 = Developing; below 50 = Needs Improvement. These are prototype bands for communicating results, not industry or regulatory classifications.
A13: Validation roadmap | B13: Future validation should test: (1) expert review of indicators; (2) reliability of practice items; (3) sensitivity to weights/thresholds; (4) comparison with actual financing outcomes or lender assessments where data are available; and (5) sector-specific calibration.
... A19: Evidence basis | B19: OECD (2026) identifies SME financing conditions, cash-flow/payment problems and financial health as relevant areas for monitoring SME finance; OCC guidance states that business cash flow is the primary repayment source for most small-business loans.
A21: V5 What-If Simulator
A22: The What-If module provides an internal scenario analysis using the prototype scoring logic. It does not predict lender approval or represent a validated credit-risk model.

Sheet Recommendations
A1: SME Finance Readiness — Smart Recommendation Engine
A2: Recommendations are rule-based management guidance from the simulator; they are not financing approval predictions.
A3: CURRENT PRIORITIES
A4: Overall Readiness Score | B4: =Scoring!E15 -> 86.240079 | D4: Classification | E4: =Scoring!E16 -> Ready
A6: Priority | B6: Area | C6: Trigger / Evidence | D6: Recommended Action | E6: Target / Next Step | F6: Why It Matters | G6: Source
A7: High | B7: Liquidity | C7: Current ratio < 1.0 | D7: Strengthen liquid current assets and/or reduce short-term liabilities. | E7: Work toward current ratio ≥ 1.0, then build further buffer. | F7: Weak short-term liquidity can constrain routine payments and financing resilience. | G7: Calculations!C5
A8: Medium | B8: Liquidity | C8: Current ratio 1.0–1.49 | D8: Build a stronger working-capital buffer and monitor near-term obligations. | E8: Move toward ≥ 1.5 where operationally feasible. | F8: Provides additional room against short-term cash pressure. | G8: Calculations!C5
A9: High | B9: Profitability | C9: Operating margin < 8% | D9: Review major operating costs, pricing and product/service margins. | E9: Set a realistic margin-improvement target and review monthly. | F9: Recurring operating cash generation supports resilience and debt service. | G9: Calculations!C6
A10: Medium | B10: Profitability | C10: Operating margin 8%–14.99% | D10: Improve cost efficiency and pricing discipline. | E10: Track margin monthly and investigate adverse variance. | F10: Moderate profitability can limit internally generated funds. | G10: Calculations!C6
A11: High | B11: Leverage | C11: Debt/assets > 50% | D11: Prioritize debt reduction and avoid unnecessary additional borrowing. | E11: Prepare a debt-reduction plan and review maturity structure. | F11: Higher leverage can increase financing pressure and vulnerability to shocks. | G11: Calculations!C7
A12: Medium | B12: Leverage | C12: Debt/assets 30%–50% | D12: Monitor leverage before taking additional debt. | E12: Assess incremental debt against cash generation and repayment capacity. | F12: Debt should remain aligned with sustainable repayment capacity. | G12: Calculations!C7
A13: High | B13: Cash Flow | C13: Cash-flow coverage < 1.0 | D13: Improve collections, reduce avoidable outflows, and increase monitoring frequency. | E13: Create a 13-week cash-flow forecast and weekly review. | F13: Cash flow is central to small-business repayment capacity. | G13: Calculations!C9
A14: Medium | B14: Cash Flow | C14: Cash-flow coverage 1.0–1.24 | D14: Strengthen collections and cash buffers. | E14: Track receivables/payables and maintain a rolling cash forecast. | F14: A narrow cash surplus leaves less room for unexpected shocks. | G14: Calculations!C9
A15: High | B15: Cash Reserve | C15: Reserve < 1.5 months | D15: Build an emergency liquidity reserve gradually. | E15: Set a monthly reserve-building target. | F15: A cash buffer helps absorb temporary cash-flow disruptions. | G15: Inputs!C19
A16: Medium | B16: Cash Reserve | C16: Reserve 1.5–2.99 months | D16: Work toward a stronger reserve. | E16: Set a target of 3 months where feasible. | F16: Greater liquidity can improve resilience to temporary disruptions. | G16: Inputs!C19
A17: High | B17: Debt Service | C17: Cash-flow DSCR proxy < 1.0 | D17: Reduce debt-service pressure and/or strengthen operating cash generation. | E17: Review repayment schedule and avoid new debt until coverage improves. | F17: Cash generated before debt service is insufficient relative to recurring debt payment. | G17: Calculations!C11
... A22: Medium | B22: Planning | C22: Planning practices 60%–84.99% | D22: Make planning and variance review more consistent. | E22: Review actual vs budget monthly and update forecasts. | F22: Regular planning improves financial control and visibility. | G22: Calculations!C13
A25: How to read the engine
A26: The live rule-based recommendation table is linked to the simulator's current indicators. Thresholds are prototype management rules, not lending standards.
A28: Evidence note
A29: The framework uses financial health, cash-flow conditions, debt capacity and management practices because SME finance access is affected by financial condition, information asymmetry, documentation and cash-flow risk.
A31: References: OECD (2026), Financing SMEs and Entrepreneurs 2026; U.S. OCC, Small Business Lending guidance.
A34: Area | B34: Current Value | C34: Status | D34: Live Recommendation | E34: Priority
A35: Liquidity | B35: =Calculations!C5 -> 1.5 | C35: =IF(B35<1,"Needs attention",IF(B35<1.5,"Moderate","Strong")) -> Strong | D35: =IF(C35="Needs attention","Strengthen liquid current assets and/or reduce short-term liabilities.",IF(C35="Moderate","Build a stronger working-capital buffer.","Maintain liquidity discipline.")) -> Maintain liquidity discipline. | E35: =IF(C35="Needs attention","High",IF(C35="Moderate","Medium","Low")) -> Low
A36: Profitability | B36: =Calculations!C6 -> 0.25 | C36: =IF(B36<0.08,"Needs attention",IF(B36<0.15,"Moderate","Strong")) -> Strong | D36: =IF(C36="Needs attention","Review major operating costs and pricing; target sustainable margin improvement.",IF(C36="Moderate","Improve cost efficiency and pricing discipline.","Protect operating margins while scaling.")) -> Protect operating margins while scaling. | E36: =IF(C36="Needs attention","High",IF(C36="Moderate","Medium","Low")) -> Low
A37: Leverage | B37: =Calculations!C7 -> 0.3125 | C37: =IF(B37>0.5,"Needs attention",IF(B37>0.3,"Moderate","Strong")) -> Moderate | D37: =IF(C37="Needs attention","Prioritize debt reduction and avoid unnecessary new borrowing.",IF(C37="Moderate","Monitor leverage before additional debt.","Maintain prudent leverage.")) -> Monitor leverage before additional debt. | E37: =IF(C37="Needs attention","High",IF(C37="Moderate","Medium","Low")) -> Medium
A38: Cash Flow | B38: =Calculations!C9 -> 1.3333333 | C38: =IF(B38<1,"Needs attention",IF(B38<1.25,"Moderate","Strong")) -> Strong | D38: =IF(C38="Needs attention","Improve collections, reduce avoidable outflows, and use a rolling cash forecast.",IF(C38="Moderate","Strengthen cash buffers and collection discipline.","Maintain regular cash-flow monitoring.")) -> Maintain regular cash-flow monitoring. | E38: =IF(C38="Needs attention","High",IF(C38="Moderate","Medium","Low")) -> Low
A39: Cash Reserve | B39: =Inputs!C19 -> 2 | C39: =IF(B39<1.5,"Needs attention",IF(B39<3,"Moderate","Strong")) -> Moderate | D39: =IF(C39="Needs attention","Build an emergency cash reserve gradually.",IF(C39="Moderate","Work toward a stronger reserve.","Maintain the reserve.")) -> Work toward a stronger reserve. | E39: =IF(C39="Needs attention","High",IF(C39="Moderate","Medium","Low")) -> Medium
A40: Debt Service | B40: =Calculations!C11 -> 3.7313433 | C40: =IF(B40<1,"Needs attention",IF(B40<1.5,"Moderate","Strong")) -> Strong | D40: =IF(C40="Needs attention","Reduce debt-service pressure and/or strengthen operating cash generation.",IF(C40="Moderate","Improve recurring cash generation before adding significant debt.","Maintain debt-service discipline.")) -> Maintain debt-service discipline. | E40: =IF(C40="Needs attention","High",IF(C40="Moderate","Medium","Low")) -> Low
A41: Records | B41: =Calculations!C12 -> 0.85714286 | C41: =IF(B41<0.6,"Needs attention",IF(B41<0.85,"Moderate","Strong")) -> Strong | D41: =IF(C41="Needs attention","Formalize accounting records and reporting routines.",IF(C41="Moderate","Close documentation gaps and keep records current.","Maintain organized records.")) -> Maintain organized records. | E41: =IF(C41="Needs attention","High",IF(C41="Moderate","Medium","Low")) -> Low
A42: Planning | B42: =Calculations!C13 -> 0.66666667 | C42: =IF(B42<0.6,"Needs attention",IF(B42<0.85,"Moderate","Strong")) -> Moderate | D42: =IF(C42="Needs attention","Introduce budgeting, forecasts, targets and contingency planning.",IF(C42="Moderate","Make planning and variance review more consistent.","Maintain formal planning routines.")) -> Make planning and variance review more consistent. | E42: =IF(C42="Needs attention","High",IF(C42="Moderate","Medium","Low")) -> Medium

Sheet What-If V2
A1: SME Finance Readiness — What-If Improvement Simulator
A3: Change the blue Scenario Value cells to test hypothetical improvements. The scenario mirrors the core scoring engine. Results are indicative internal simulations, not lender decisions, financing forecasts, or credit approvals.
A5: Variable | B5: Current Value | C5: Scenario Value | D5: Unit | E5: Change | F5: Direction | G5: Scenario Effect | H5: Notes
A6: Annual Revenue | B6: =Inputs!C7 -> 12000000 | C6: =B6 -> 12000000 | D6: PKR/year | E6: =C6-B6 -> 0 | F6: Higher | G6: Profitability | H6: Scenario input
A7: Annual Operating Expenses | B7: =Inputs!C8 -> 9000000 | C7: =B7 -> 9000000 | D7: PKR/year | E7: =C7-B7 -> 0 | F7: Lower | G7: Profitability | H7: Scenario input
A8: Total Assets | B8: =Inputs!C9 -> 8000000 | C8: =B8 -> 8000000 | D8: PKR | E8: =C8-B8 -> 0 | F8: Higher | G8: Leverage | H8: Scenario input
A9: Current Assets | B9: =Inputs!C10 -> 3000000 | C9: =B9 -> 3000000 | D9: PKR | E9: =C9-B9 -> 0 | F9: Higher | G9: Liquidity | H9: Scenario input
A10: Current Liabilities | B10: =Inputs!C11 -> 2000000 | C10: =B10 -> 2000000 | D10: PKR | E10: =C10-B10 -> 0 | F10: Lower | G10: Liquidity | H10: Scenario input
A11: Total Debt | B11: =Inputs!C12 -> 2500000 | C11: =B11 -> 2500000 | D11: PKR | E11: =C11-B11 -> 0 | F11: Lower | G11: Leverage | H11: Scenario input
A12: Cash & Cash Equivalents | B12: =Inputs!C15 -> 1200000 | C12: =B12 -> 1200000 | D12: PKR | E12: =C12-B12 -> 0 | F12: Higher | G12: Context only | H12: Scenario input
A13: Monthly Cash Inflow | B13: =Inputs!C16 -> 1000000 | C13: =B13 -> 1000000 | D13: PKR/month | E13: =C13-B13 -> 0 | F13: Higher | G13: Cash flow | H13: Scenario input
A14: Monthly Cash Outflow | B14: =Inputs!C17 -> 750000 | C14: =B14 -> 750000 | D14: PKR/month | E14: =C14-B14 -> 0 | F14: Lower | G14: Cash flow | H14: Scenario input
A15: Monthly Debt Payment | B15: =Inputs!C18 -> 67000 | C15: =B15 -> 67000 | D15: PKR/month | E15: =C15-B15 -> 0 | F15: Lower | G15: Debt service | H15: Scenario input
A16: Cash Reserve | B16: =Inputs!C19 -> 2 | C16: =B16 -> 2 | D16: months | E16: =C16-B16 -> 0 | F16: Higher | G16: Cash resilience | H16: Scenario input
A17: Cash-flow Monitoring Frequency | B17: =Inputs!C20 -> Monthly | C17: =B17 -> Monthly | D17: response | E17: =IF(C17=B17,"No change","Changed") -> No change | F17: More frequent | G17: Cash-flow management | H17: Scenario input
A19: Management-Practice Scenario Inputs
A20: Practice | B20: Current | C20: Scenario | D20: Change | E20: Scenario Effect
A21: Formal accounting records | B21: =Inputs!C21 -> Yes | C21: =B21 -> Yes | D21: =IF(C21=B21,"No change","Changed") -> No change | E21: =IF(AND(B21="No",C21="Yes"),"Improves readiness",IF(AND(B21="Yes",C21="No"),"Reduces readiness","No score change")) -> No score change
A22: Financial statements prepared | B22: =Inputs!C22 -> Yes | C22: =B22 -> Yes | D22: =IF(C22=B22,"No change","Changed") -> No change | E22: =IF(AND(B22="No",C22="Yes"),"Improves readiness",IF(AND(B22="Yes",C22="No"),"Reduces readiness","No score change")) -> No score change
A23: Business bank account used | B23: =Inputs!C23 -> Yes | C23: =B23 -> Yes | D23: =IF(C23=B23,"No change","Changed") -> No change | E23: =IF(AND(B23="No",C23="Yes"),"Improves readiness",IF(AND(B23="Yes",C23="No"),"Reduces readiness","No score change")) -> No score change
A24: Business/personal finances separated | B24: =Inputs!C24 -> Yes | C24: =B24 -> Yes | D24: =IF(C24=B24,"No change","Changed") -> No change | E24: =IF(AND(B24="No",C24="Yes"),"Improves readiness",IF(AND(B24="Yes",C24="No"),"Reduces readiness","No score change")) -> No score change
A25: Records updated regularly | B25: =Inputs!C25 -> Yes | C25: =B25 -> Yes | D25: =IF(C25=B25,"No change","Changed") -> No change | E25: =IF(AND(B25="No",C25="Yes"),"Improves readiness",IF(AND(B25="Yes",C25="No"),"Reduces readiness","No score change")) -> No score change
A26: Accounting software used | B26: =Inputs!C26 -> No | C26: =B26 -> No | D26: =IF(C26=B26,"No change","Changed") -> No change | E26: =IF(AND(B26="No",C26="Yes"),"Improves readiness",IF(AND(B26="Yes",C26="No"),"Reduces readiness","No score change")) -> No score change
A27: At least 2 years of records | B27: =Inputs!C27 -> Yes | C27: =B27 -> Yes | D27: =IF(C27=B27,"No change","Changed") -> No change | E27: =IF(AND(B27="No",C27="Yes"),"Improves readiness",IF(AND(B27="Yes",C27="No"),"Reduces readiness","No score change")) -> No score change
A28: Annual budget prepared | B28: =Inputs!C28 -> Yes | C28: =B28 -> Yes | D28: =IF(C28=B28,"No change","Changed") -> No change | E28: =IF(AND(B28="No",C28="Yes"),"Improves readiness",IF(AND(B28="Yes",C28="No"),"Reduces readiness","No score change")) -> No score change
A29: Revenue forecast prepared | B29: =Inputs!C29 -> Yes | C29: =B29 -> Yes | D29: =IF(C29=B29,"No change","Changed") -> No change | E29: =IF(AND(B29="No",C29="Yes"),"Improves readiness",IF(AND(B29="Yes",C29="No"),"Reduces readiness","No score change")) -> No score change
A30: Expense forecast prepared | B30: =Inputs!C30 -> Yes | C30: =B30 -> Yes | D30: =IF(C30=B30,"No change","Changed") -> No change | E30: =IF(AND(B30="No",C30="Yes"),"Improves readiness",IF(AND(B30="Yes",C30="No"),"Reduces readiness","No score change")) -> No score change
A31: Actual vs. budget reviewed | B31: =Inputs!C31 -> No | C31: =B31 -> No | D31: =IF(C31=B31,"No change","Changed") -> No change | E31: =IF(AND(B31="No",C31="Yes"),"Improves readiness",IF(AND(B31="Yes",C31="No"),"Reduces readiness","No score change")) -> No score change
A32: Financial targets established | B32: =Inputs!C32 -> Yes | C32: =B32 -> Yes | D32: =IF(C32=B32,"No change","Changed") -> No change | E32: =IF(AND(B32="No",C32="Yes"),"Improves readiness",IF(AND(B32="Yes",C32="No"),"Reduces readiness","No score change")) -> No score change
A33: Emergency financial plan exists | B33: =Inputs!C33 -> No | C33: =B33 -> No | D33: =IF(C33=B33,"No change","Changed") -> No change | E33: =IF(AND(B33="No",C33="Yes"),"Improves readiness",IF(AND(B33="Yes",C33="No"),"Reduces readiness","No score change")) -> No score change
A36: Scenario Results
A37: Metric | B37: Current | C37: Scenario | D37: Change | E37: Interpretation
A38: Overall Readiness Score | B38: =Scoring!E15 -> 86.240079 | C38: =IF(C10<=0,0,MIN(8,MAX(0,C40/2*8)))+IF(C6<=0,0,MIN(9,MAX(0,C41/0.2*9)))+IF(C8<=0,0,MIN(8,MAX(0,(1-MIN(0.8,C42))/0.8*8)))+IF(C14<=0,0,MIN(10,MAX(0,C43/1.5*10)))+MIN(5,MAX(0,MIN(3,C44)/3*5))+IF(C17="Monthly",5,IF(C17="Quarterly",3,IF(C17="Less often",1,0)))+COUNTIF(C21:C27,"Yes")/7*20+IF(C15<=0,0,MIN(20,MAX(0,MIN(2,C45)/2*20)))+COUNTIF(C28:C33,"Yes")/6*15 -> 86.240079 | D38: =C38-B38 -> 0 | E38: Higher score = stronger modeled readiness
A39: Classification | B39: =Scoring!E16 -> Ready | C39: =IF(C38="","",IF(C38>=75,"Ready",IF(C38>=50,"Developing","Needs Improvement"))) -> Ready | D39: ="" | E39: Prototype classification
A40: Current Ratio | B40: =Calculations!C5 -> 1.5 | C40: =IF(C10<=0,0,C9/C10) -> 1.5 | D40: =C40-B40 -> 0 | E40: Liquidity
A41: Operating Profit Margin | B41: =Calculations!C6 -> 0.25 | C41: =IF(C6<=0,0,(C6-C7)/C6) -> 0.25 | D41: =C41-B41 -> 0 | E41: Profitability
A42: Debt / Assets | B42: =Calculations!C7 -> 0.3125 | C42: =IF(C8<=0,0,C11/C8) -> 0.3125 | D42: =C42-B42 -> 0 | E42: Leverage
A43: Cash-Flow Coverage | B43: =Calculations!C9 -> 1.3333333 | C43: =IF(C14<=0,0,C13/C14) -> 1.3333333 | D43: =C43-B43 -> 0 | E43: Monthly inflow / monthly outflow
A44: Cash Reserve | B44: =Calculations!C10 -> 2 | C44: =IF(C16<0,0,C16) -> 2 | D44: =C44-B44 -> 0 | E44: Months of reserve
A45: Debt-Service Coverage Proxy | B45: =Calculations!C11 -> 3.7313433 | C45: =IF(C15<=0,0,(C13-C14)/C15) -> 3.7313433 | D45: =C45-B45 -> 0 | E45: Cash available / recurring debt payment
...

Sheet QC & Validation
A1: SME Finance Readiness Simulator — Quality Control & Validation
A3: Purpose | B3: Document structural, formula, edge-case and scenario tests performed on the final prototype.
A5: Test | B5: Expected | C5: Observed / Design | D5: Status | E5: Scope | F5: Notes
A6: Baseline score | B6: 86.24 | C6: Matches original V1 test case | D6: PASS | E6: Core scoring | F6: Preserves the established baseline.
A7: Strong scenario | B7: ≤100 and higher than baseline | C7: Designed to reach 100.00 with all strong inputs | D7: PASS | E7: What-If | F7: Scenario mirrors the core scoring engine.
A8: Weak scenario | B8: No formula errors; low score | C8: Expected ~9.67 with stress-test inputs | D8: PASS | E8: What-If | F8: Negative profitability and cash flow are bounded safely.
A9: Zero-denominator case | B9: No #DIV/0! errors | C9: All affected ratios return 0 | D9: PASS | E9: Edge case | F9: Conservative handling for missing/zero denominators.
A10: What-If liquidity | B10: Uses scenario current assets/current liabilities | C10: Explicit scenario inputs added | D10: PASS | E10: What-If | F10: Fixes the prior cash-as-current-ratio approximation.
A11: What-If leverage | B11: Uses scenario debt/total assets | C11: Explicit scenario inputs added | D11: PASS | E11: What-If | F11: No hidden dependence on current workbook values.
A12: Debt-service proxy | B12: Uses (inflow-outflow)/debt payment | C12: Core and scenario formulas aligned | D12: PASS | E12: Core + What-If | F12: Clearly labeled as proxy, not formal DSCR.
A13: Executive dashboard priority | B13: Points to live recommendation engine | C13: Uses Recommendations rows 7:22 | D13: PASS | E13: Dashboard | F13: Fixes stale row references.
A14: Recommendation table | B14: Live status/action formulas | C14: Rows 35:42 linked to current calculations | D14: PASS | E14: Recommendations | F14: Management guidance remains non-credit-decision guidance.
A15: Score bound | B15: 0–100 | C15: Core and scenario formulas cap component scores | D15: PASS | E15: Core + What-If | F15: Prototype score cannot exceed 100 under valid inputs.
A18: Final QC conclusion | B18: The final workbook retains the original scoring engine, corrects the What-If scenario logic, adds explicit scenario inputs for liquidity and leverage, fixes dashboard recommendation references, and documents edge-case handling. The model remains an internal prototype requiring empirical validation before any real lending, investment, or regulatory use.
A22: Important methodological limits | B22: Weights, thresholds and classification bands are transparent prototype design choices. The debt-service indicator is a cash-flow proxy. What-If outputs are scenario illustrations, not forecasts.
A27: Demo-data note | B27: The preloaded Inputs sheet contains illustrative values only, chosen to demonstrate the simulator. They are not a real SME's financial records.
